<?xml version="1.0" ?>
<!-- =================================================================================== -->
<!-- |    This document was autogenerated by xacro from lwa4p.xacro                    | -->
<!-- |    EDITING THIS FILE BY HAND IS NOT RECOMMENDED                                 | -->
<!-- =================================================================================== -->
<robot name="schunk_lwa4p">
  <!-- joint between base_link and lwa4p_extended_connector_link -->
  <link name="world"/>
  <joint name="lwa4p_base_joint" type="fixed">
    <origin rpy="0 0 0" xyz="0 0 0"/>
    <parent link="world"/>
    <child link="lwa4p_base_link"/>
  </joint>
  <link name="lwa4p_base_link">
    <inertial>
      <mass value="0.01"/>
      <origin xyz="0 0 0"/>
      <inertia ixx="0.001" ixy="0.0" ixz="0.0" iyy="0.001" iyz="0.0" izz="0.001"/>
    </inertial>
  </link>
  <!-- joint between arm_0_link and arm_1_link -->
  <joint name="lwa4p_1_joint" type="revolute">
    <origin rpy="0 0 0" xyz="0 0 0"/>
    <parent link="lwa4p_base_link"/>
    <child link="lwa4p_1_link"/>
    <axis xyz="0 0 1"/>
    <limit effort="370" lower="-2.947" upper="2.947" velocity="1.26"/>
    <!--safety_controller k_position="20" k_velocity="50" soft_lower_limit="${-6.28 + 0.01}" soft_upper_limit="${6.28 - 0.01}" /-->
  </joint>
  <link name="lwa4p_1_link">
    <inertial>
      <mass value="0.01"/>
      <origin xyz="0 0 0"/>
      <inertia ixx="0.001" ixy="0.0" ixz="0.0" iyy="0.001" iyz="0.0" izz="0.001"/>
    </inertial>
    <!--
      <inertial>
        <origin xyz="0 0 0" rpy="0 0 0" />
        <mass value="0.29364"/>
        <inertia ixx="0.01" ixy="0" ixz="0" iyy="0.01" iyz="0" izz="0.01" />
      </inertial>
-->
    <visual>
      <origin rpy="0 0 0" xyz="0 0 0"/>
      <geometry>
        <mesh filename="meshes/lwa4p/arm_1_link.dae"/>
      </geometry>
      <material name="Schunk/Blue"/>
    </visual>
    <collision>
      <origin rpy="0 0 0" xyz="0 0 0"/>
      <geometry>
        <mesh filename="meshes/lwa4p/arm_1_link.stl"/>
      </geometry>
    </collision>
  </link>
  <!-- joint between arm_1_link and arm_2_link -->
  <joint name="lwa4p_2_joint" type="revolute">
    <origin rpy="1.5708 0 0" xyz="0 0 0"/>
    <parent link="lwa4p_1_link"/>
    <child link="lwa4p_2_link"/>
    <axis xyz="0 0 1"/>
    <limit effort="370" lower="-2.947" upper="2.947" velocity="1.26"/>
    <!--safety_controller k_position="20" k_velocity="50" soft_lower_limit="${-2.09 + 0.01}" soft_upper_limit="${2.09 - 0.01}" /-->
  </joint>
  <link name="lwa4p_2_link">
    <inertial>
      <mass value="0.01"/>
      <origin xyz="0 0 0"/>
      <inertia ixx="0.001" ixy="0.0" ixz="0.0" iyy="0.001" iyz="0.0" izz="0.001"/>
    </inertial>
    <!--
      <inertial>
        <origin xyz="0 0 0" rpy="0 0 0"/>
        <mass value="1.68311"/>
        <inertia ixx="0.03" ixy="0" ixz="0" iyy="0.03" iyz="0" izz="0.03" />
      </inertial>
-->
    <visual>
      <origin rpy="0 0 0" xyz="0 0 0"/>
      <geometry>
        <mesh filename="meshes/lwa4p/arm_2_link.dae"/>
      </geometry>
      <material name="Schunk/LightGrey"/>
    </visual>
    <collision>
      <origin rpy="0 0 0" xyz="0 0 0"/>
      <geometry>
        <mesh filename="meshes/lwa4p/arm_2_link.stl"/>
      </geometry>
    </collision>
  </link>
  <!-- joint between arm_2_link and arm_3_link -->
  <joint name="lwa4p_3_joint" type="revolute">
    <origin rpy="0 3.14159 0" xyz="0 0.350 0"/>
    <parent link="lwa4p_2_link"/>
    <child link="lwa4p_3_link"/>
    <axis xyz="0 0 1"/>
    <limit effort="176" lower="-2.694" upper="2.694" velocity="1.26"/>
    <!--safety_controller k_position="20" k_velocity="25" soft_lower_limit="${-6.28 + 0.01}" soft_upper_limit="${6.28 - 0.01}" /-->
  </joint>
  <link name="lwa4p_3_link">
    <inertial>
      <mass value="0.01"/>
      <origin xyz="0 0 0"/>
      <inertia ixx="0.001" ixy="0.0" ixz="0.0" iyy="0.001" iyz="0.0" izz="0.001"/>
    </inertial>
    <!--
      <inertial>
        <origin xyz="0 0 0" rpy="0 0 0"/>
        <mass value="2.1"/>
        <inertia ixx="0.03" ixy="0" ixz="0" iyy="0.03" iyz="0" izz="0.03" />
      </inertial>
-->
    <visual>
      <origin rpy="0 0 0" xyz="0 0 0"/>
      <geometry>
        <mesh filename="meshes/lwa4p/arm_3_link.dae"/>
      </geometry>
      <material name="Schunk/Blue"/>
    </visual>
    <collision>
      <origin rpy="0 0 0" xyz="0 0 0"/>
      <geometry>
        <mesh filename="meshes/lwa4p/arm_3_link.stl"/>
      </geometry>
    </collision>
  </link>
  <!-- joint between arm_3_link and arm_4_link -->
  <joint name="lwa4p_4_joint" type="revolute">
    <origin rpy="-1.5708 3.14159 0" xyz="0 0 0"/>
    <parent link="lwa4p_3_link"/>
    <child link="lwa4p_4_link"/>
    <axis xyz="0 0 1"/>
    <limit effort="176" lower="-2.947" upper="2.947" velocity="1.26"/>
    <!--safety_controller k_position="20" k_velocity="25" soft_lower_limit="${-2.09 + 0.01}" soft_upper_limit="${2.09 - 0.01}" /-->
  </joint>
  <link name="lwa4p_4_link">
    <inertial>
      <mass value="0.01"/>
      <origin xyz="0 0 0"/>
      <inertia ixx="0.001" ixy="0.0" ixz="0.0" iyy="0.001" iyz="0.0" izz="0.001"/>
    </inertial>
    <!--
      <inertial>
        <origin xyz="0 0 0" rpy="0 0 0"/>
        <mass value="1.68311"/>
        <inertia ixx="0.03" ixy="0" ixz="0" iyy="0.03" iyz="0" izz="0.03" />
      </inertial>
-->
    <visual>
      <origin rpy="0 0 0" xyz="0 0 0"/>
      <geometry>
        <mesh filename="meshes/lwa4p/arm_4_link.dae"/>
      </geometry>
      <material name="Schunk/LightGrey"/>
    </visual>
    <collision>
      <origin rpy="0 0 0" xyz="0 0 0"/>
      <geometry>
        <mesh filename="meshes/lwa4p/arm_4_link.stl"/>
      </geometry>
    </collision>
  </link>
  <!-- joint between arm_4_link and arm_5_link -->
  <joint name="lwa4p_5_joint" type="revolute">
    <origin rpy="1.5708 0 3.14159" xyz="0 0.005263 0.305"/>
    <parent link="lwa4p_4_link"/>
    <child link="lwa4p_5_link"/>
    <axis xyz="0 0 1"/>
    <limit effort="41.6" lower="-2.947" upper="2.947" velocity="1.26"/>
    <!--safety_controller k_position="20" k_velocity="25" soft_lower_limit="${-6.28 + 0.01}" soft_upper_limit="${6.28 - 0.01}" /-->
  </joint>
  <link name="lwa4p_5_link">
    <inertial>
      <mass value="0.01"/>
      <origin xyz="0 0 0"/>
      <inertia ixx="0.001" ixy="0.0" ixz="0.0" iyy="0.001" iyz="0.0" izz="0.001"/>
    </inertial>
    <!--
      <inertial>
        <origin xyz="0 0 0" rpy="0 0 0"/>
        <mass value="0.807"/>
        <inertia ixx="0.03" ixy="0" ixz="0" iyy="0.03" iyz="0" izz="0.03" />
      </inertial>
-->
    <visual>
      <origin rpy="0 0 0" xyz="0 0 0"/>
      <geometry>
        <mesh filename="meshes/lwa4p/arm_5_link.dae"/>
      </geometry>
      <material name="Schunk/Blue"/>
    </visual>
    <collision>
      <origin rpy="0 0 0" xyz="0 0 0"/>
      <geometry>
        <mesh filename="meshes/lwa4p/arm_5_link.stl"/>
      </geometry>
    </collision>
  </link>


  <!-- joint between arm_5_link and arm_6_link -->
  <joint name="lwa4p_6_joint" type="revolute">
    <origin rpy="-1.5708 0 0" xyz="0 0 0"/>
    <parent link="lwa4p_5_link"/>
    <child link="lwa4p_6_link"/>
    <axis xyz="0 0 1"/>
    <limit effort="20.1" lower="-2.947" upper="2.947" velocity="1.26"/>
    <!--safety_controller k_position="20" k_velocity="25" soft_lower_limit="${-2.09 + 0.01}" soft_upper_limit="${2.09 - 0.01}" /-->
  </joint>
  <link name="lwa4p_6_link">
    <inertial>
      <mass value="0.01"/>
      <origin xyz="0 0 0"/>
      <inertia ixx="0.001" ixy="0.0" ixz="0.0" iyy="0.001" iyz="0.0" izz="0.001"/>
    </inertial>
    <!--
      <inertial>
        <origin xyz="0 0 0" rpy="0 0 0"/>
        <mass value="0.819"/>
        <inertia ixx="0.01" ixy="0" ixz="0" iyy="0.01" iyz="0" izz="0.01" />
      </inertial>
-->
    <visual>
      <origin rpy="0 0 0" xyz="0 0 0"/>
      <geometry>
        <mesh filename="meshes/lwa4p/arm_6_link.dae"/>
      </geometry>
      <material name="Schunk/LightGrey"/>
    </visual>
    <collision>
      <origin rpy="0 0 0" xyz="0 0 0"/>
      <geometry>
        <mesh filename="meshes/lwa4p/arm_6_link.stl"/>
      </geometry>
    </collision>
  </link>

  <joint name="lwa4p_ee_joint" type="fixed">
        <origin rpy="0 0 0" xyz="0 0 0.0824"/>
        <parent link="lwa4p_6_link"/>
        <child link="lwa4p_ee_link"/>
  </joint>
  <link name="lwa4p_ee_link">
        <inertial>
          <mass value="0.01"/>
          <origin xyz="0 0 0"/>
          <inertia ixx="0.001" ixy="0.0" ixz="0.0" iyy="0.001" iyz="0.0" izz="0.001"/>
        </inertial>
  </link>

  <gazebo reference="lwa4p_0_link">
    <gravity>true</gravity>
    <self_collide>false</self_collide>
    <material value="Schunk/LightGrey"/>
  </gazebo>
  <gazebo reference="lwa4p_1_link">
    <gravity>true</gravity>
    <self_collide>false</self_collide>
    <material value="Schunk/Blue"/>
  </gazebo>
  <gazebo reference="lwa4p_2_link">
    <gravity>true</gravity>
    <self_collide>false</self_collide>
    <material value="Schunk/LightGrey"/>
  </gazebo>
  <gazebo reference="lwa4p_3_link">
    <gravity>true</gravity>
    <self_collide>false</self_collide>
    <material value="Schunk/Blue"/>
  </gazebo>
  <gazebo reference="lwa4p_4_link">
    <gravity>true</gravity>
    <self_collide>false</self_collide>
    <material value="Schunk/LightGrey"/>
  </gazebo>
  <gazebo reference="lwa4p_5_link">
    <gravity>true</gravity>
    <self_collide>false</self_collide>
    <material value="Schunk/Blue"/>
  </gazebo>
  <gazebo reference="lwa4p_6_link">
    <gravity>true</gravity>
    <self_collide>false</self_collide>
    <material value="Schunk/LightGrey"/>
  </gazebo>


</robot>

